{"uuid": "d398ee48-7654-42c2-adeb-b8e2c51f2b8e", "children": ["1d959897-e73b-452e-940c-7216a68464bf", "05d47ea2-45c7-4f1d-afa8-592b49108870"], "befores": [{"name": "_UnitTestCase__pytest_class_setup", "status": "broken", "statusDetails": {"message": "selenium.common.exceptions.WebDriverException: Message: An unknown server-side error occurred while processing the command. Original error: Could not find a connected Android device.\n\n", "trace": "  File \"c:\\users\\x\\appdata\\local\\programs\\python\\python37\\lib\\site-packages\\pluggy\\callers.py\", line 187, in _multicall\n    res = hook_impl.function(*args)\n  File \"c:\\users\\x\\appdata\\local\\programs\\python\\python37\\lib\\site-packages\\_pytest\\fixtures.py\", line 1117, in pytest_fixture_setup\n    result = call_fixture_func(fixturefunc, request, kwargs)\n  File \"c:\\users\\x\\appdata\\local\\programs\\python\\python37\\lib\\site-packages\\_pytest\\fixtures.py\", line 915, in call_fixture_func\n    fixture_result = next(generator)\n  File \"c:\\users\\x\\appdata\\local\\programs\\python\\python37\\lib\\site-packages\\_pytest\\unittest.py\", line 131, in fixture\n    setup()\n  File \"D:\\code\\webauto\\hmtt\\case\\app\\test_query_aritcal.py\", line 13, in setUpClass\n    cls.driver = DriverUtils.get_app_driver()\n  File \"D:\\code\\webauto\\hmtt\\utils.py\", line 94, in get_app_driver\n    cls.__app_driver = appium.webdriver.Remote('http://localhost:4723/wd/hub', desired_caps)\n  File \"c:\\users\\x\\appdata\\local\\programs\\python\\python37\\lib\\site-packages\\appium\\webdriver\\webdriver.py\", line 155, in __init__\n    proxy\n  File \"c:\\users\\x\\appdata\\local\\programs\\python\\python37\\lib\\site-packages\\selenium\\webdriver\\remote\\webdriver.py\", line 157, in __init__\n    self.start_session(capabilities, browser_profile)\n  File \"c:\\users\\x\\appdata\\local\\programs\\python\\python37\\lib\\site-packages\\appium\\webdriver\\webdriver.py\", line 225, in start_session\n    response = self.execute(RemoteCommand.NEW_SESSION, parameters)\n  File \"c:\\users\\x\\appdata\\local\\programs\\python\\python37\\lib\\site-packages\\selenium\\webdriver\\remote\\webdriver.py\", line 321, in execute\n    self.error_handler.check_response(response)\n  File \"c:\\users\\x\\appdata\\local\\programs\\python\\python37\\lib\\site-packages\\selenium\\webdriver\\remote\\errorhandler.py\", line 242, in check_response\n    raise exception_class(message, screen, stacktrace)\n"}, "start": 1598590237148, "stop": 1598590281669}], "start": 1598590237148, "stop": 1598590281797}